Workbook
Name postcode: #REF!
Name postcode2: #REF!
Name Postcodes: 'Postal Codes 1'!$B$2:$C$1540
Name ProductName: 'Task 4.4'!#REF!
Name ProductName: 'Task 4.3'!$R$4:$U$13
Name test: 'Postal Codes 1'!$B$1:$C$1540

Sheet Task 4.0
A1: ID | B1: First Name | C1: Last Name | D1: Title | E1: Gender | F1: Credit | G1: Street | H1: Town | I1: Order Date | J1: Quantity | K1: Product
A2: 1 | B2: Nanci | C2: Camp | D2: Mrs | E2: F | F2: 60 | G2: Rosmore Road | H2: Berkeley | I2: 39988 | J2: 13 | K2: A1 | M2: STEPS
A3: 2 | B3: Erlinda | C3: Dorsey | D3: Mrs | E3: F | F3: 90 | G3: Roxwell Road | H3: Glossop | I3: 39770 | J3: 14 | K3: C3 | M3: Imported the data from the Access database file named "Portfolio4.accdb" using Data Menu
A4: 3 | B4: Albertha | C4: Devine | D4: Mrs | E4: F | F4: 60 | G4: Ashbury Place | H4: Immingham | I4: 39895 | J4: 23 | K4: E
A5: 4 | B5: Nathalie | C5: Washington | D5: Miss | E5: F | F5: 60 | G5: Grafton Road | H5: Broadstone | I5: 39830 | J5: 79 | K5: E | M5: Formatted the columns in the worksheet (width, number format, etc.)
A6: 5 | B6: Shonta | C6: Hedrick | D6: Miss | E6: fem | F6: 60 | G6: Beechdale Road | H6: Port Talbot | I6: 39988 | J6: 44 | K6: C3
A7: 6 | B7: Veronika | C7: Lundy | D7: Miss | E7: F | F7: 90 | G7: Katherine Gardens | H7: Ardgay | I7: 40316 | J7: 37 | K7: A3 | M7: Note: This Sheet is Password Protected, To unlock this sheet use "qwer" as password
A8: 7 | B8: Valeria | C8: Frost | D8: Mrs | E8: F | F8: 30 | G8: Ross Way | H8: Solihull | I8: 40202 | J8: 12 | K8: C2
A9: 8 | B9: Randa | C9: Woods | D9: Mrs | E9: F | F9: 30 | G9: Artisans Dwellings | H9: Tring | I9: 40497 | J9: 55 | K9: C1
A10: 9 | B10: Karole | C10: Navarro | D10: Mrs | E10: F | F10: 30 | G10: Rhoda Street | H10: St. Ives | I10: 39938 | J10: 10 | K10: C3
A11: 10 | B11: Martin | C11: Anthony | D11: Miss | E11: F | F11: 90 | G11: Iceland Road | H11: Campbeltown | I11: 40466 | J11: 76 | K11: A2
A12: 11 | B12: Shanae | C12: Roland | D12: Mrs | E12: F | F12: 90 | G12: Samels Court | H12: Newbridge | I12: 40031 | J12: 28 | K12: C2
A13: 12 | B13: Yen | C13: Culver | D13: Miss | E13: F | F13: 60 | G13: Garratt Green | H13: London | I13: 39965 | J13: 41 | K13: A2
A14: 13 | B14: Monica | C14: Doran | D14: Miss | E14: F | F14: 90 | G14: High St | H14: Caldicot | I14: 39516 | J14: 48 | K14: B
A15: 14 | B15: Laureen | C15: Richards | D15: Prof | E15: F | F15: 90 | G15: Brackenfield Close | H15: Broseley | I15: 39665 | J15: 34 | K15: C4
A16: 15 | B16: Meta | C16: Wright | D16: Mrs | E16: F | F16: 60 | G16: Bearstead Rise | H16: Y Felinheli | I16: 40337 | J16: 57 | K16: C4
A17: 16 | B17: Bobbye | C17: Vasquez | D17: Mrs | E17: F | F17: 30 | G17: Baker Road | H17: Trowbridge | I17: 40532 | J17: 59 | K17: E
A18: 17 | B18: Emily | C18: Butler | D18: Miss | E18: F | F18: 30 | G18: Telford Close | H18: Isles Of Scilly | I18: 40271 | J18: 84 | K18: C1
A19: 18 | B19: Iona | C19: Hutchinson | D19: Ms | E19: F | F19: 30 | G19: Queens Buildings | H19: Kilmacolm | I19: 40183 | J19: 39 | K19: C4
... A95: 94 | B95: Waneta | C95: Klein | D95: Miss | E95: F | F95: 60 | G95: Kidd Place | H95: Strathdon | I95: 39833 | J95: 97 | K95: C3
A96: 95 | B96: Jadwiga | C96: Contreras | E96: F | F96: 90 | G96: Little Lemon | H96: Llanrwst | I96: 40064 | J96: 24 | K96: E
A97: 96 | B97: Catherina | C97: Galvan | D97: Ms | E97: F | F97: 60 | G97: Little New | H97: Darwen | I97: 39927 | J97: 87 | K97: A2
A98: 97 | B98: Leslie | C98: Hobson | D98: Mrs | E98: F | F98: 30 | G98: Templecombe Road | H98: Plockton | I98: 40500 | J98: 41 | K98: A2
A99: 98 | B99: Jona | C99: Mcneill | D99: Miss | E99: F | F99: 90 | G99: Warner Road | H99: Coleford | I99: 40312 | J99: 68 | K99: E
A100: 99 | B100: Phylis | C100: Starks | D100: Mrs | E100: F | F100: 30 | G100: Du Burstow | H100: Surrey | I100: 40037 | J100: 47 | K100: B
A101: 100 | B101: Chasidy | C101: Pittman | D101: Miss | E101: F | F101: 90 | G101: Vine Cottages | H101: Tewkesbury | I101: 40107 | J101: 51 | K101: C1
A102: 101 | B102: Rina | C102: Hayes | D102: Mrs | E102: F | F102: 60 | G102: Jamaica Level | H102: Buxton | I102: 40000 | J102: 97 | K102: B
A103: 102 | B103: Piedad | C103: Mcmullen | D103: Miss | E103: F | F103: 90 | G103: College Yard | H103: Colchester | I103: 40526 | J103: 70 | K103: C2
A104: 103 | B104: Wanda | C104: Eubanks | D104: Mrs | E104: F | F104: 90 | G104: Woodington Close | H104: Bushmills | I104: 39760 | J104: 83 | K104: E
A105: 104 | B105: Taunya | C105: Medeiros | D105: Miss | E105: F | F105: 60 | G105: Westmoreland Mews | H105: Ross-Shire | I105: 39862 | J105: 63 | K105: A2
A106: 105 | B106: Carla | C106: Grover | D106: Mrs | E106: F | F106: 60 | G106: Deepdene Close | H106: Wotton-Under-Edge | I106: 39523 | J106: 67 | K106: C2
A107: 106 | B107: Moon | C107: Cervantes | D107: Miss | E107: F | F107: 90 | G107: Broadbridge Close | H107: Sedbergh | I107: 39698 | J107: 65 | K107: A2
A108: 107 | B108: Christin | C108: Wolfe | D108: Mrs | E108: F | F108: 30 | G108: Christchurch Mews | H108: Wells-Next-The-Sea | I108: 40106 | J108: 45 | K108: E
... A212: 211 | B212: Rebbeca | C212: Middleton | D212: Miss | E212: F | F212: 30 | G212: Harberson Road | H212: Attleborough | I212: 40078 | J212: 63 | K212: A1
A213: 212 | B213: Paula | C213: Duke | D213: Mrs | E213: F | G213: Colonial House | H213: Ammanford | I213: 39786 | J213: 15 | K213: A3
A214: 213 | B214: Kristie | C214: Santos | D214: Miss | E214: F | F214: 90 | G214: Pembridge Crescent | H214: Portsmouth | I214: 39641 | J214: 82 | K214: A3
A215: 214 | B215: Bernarda | C215: Knutson | D215: Miss | E215: F | F215: 30 | G215: Searles Close | H215: Llanfyrnach | I215: 40340 | J215: 81 | K215: C1
A216: 215 | B216: Mandy | C216: York | D216: Mrs | E216: F | F216: 60 | G216: Beatrice Place | H216: Kinlochleven | I216: 40232 | J216: 50 | K216: A1
A217: 216 | B217: Francina | C217: Corley | D217: Miss | E217: F | F217: 90 | G217: Stewart Road | H217: Ventnor | J217: 55 | K217: C2
A218: 217 | B218: Evan | C218: Holmes | D218: Mrs | E218: F | F218: 60 | G218: Stanthorpe Close | H218: Helensburgh | I218: 40439 | J218: 72 | K218: C4
...

Sheet Task 4.1 Counting Blank Cells
A1: ID | B1: First Name | C1: Last Name | D1: Title | E1: Gender | F1: Credit | G1: Street | H1: Town | I1: Order Date | J1: Quantity | K1: Product | L1: Blanks
A2: 1 | B2: Nanci | C2: Camp | D2: Mrs | E2: F | F2: 60 | G2: Rosmore Road | H2: Berkeley | I2: 39988 | J2: 13 | K2: A1 | L2: =COUNTBLANK(Portfolio43[[#This Row],[ID]:[Product]]) -> 0 | N2: STEPS
A3: 2 | B3: Erlinda | C3: Dorsey | D3: Mrs | E3: F | F3: 90 | G3: Roxwell Road | H3: Glossop | I3: 39770 | J3: 14 | K3: C3 | L3: =COUNTBLANK(Portfolio43[[#This Row],[ID]:[Product]]) -> 0 | N3: Used COUNTBLANK Function to Identify the total number of Blank Cells in the sheet
A4: 3 | B4: Albertha | C4: Devine | D4: Mrs | E4: F | F4: 60 | G4: Ashbury Place | H4: Immingham | I4: 39895 | J4: 23 | K4: E | L4: =COUNTBLANK(Portfolio43[[#This Row],[ID]:[Product]]) -> 0 | N4: Formula: | P4: COUNTBLANK(Portfolio43)
A5: 4 | B5: Nathalie | C5: Washington | D5: Miss | E5: F | F5: 60 | G5: Grafton Road | H5: Broadstone | I5: 39830 | J5: 79 | K5: E | L5: =COUNTBLANK(Portfolio43[[#This Row],[ID]:[Product]]) -> 0 | N5: Blank cells detected | P5: =COUNTBLANK(Portfolio43[]) -> 15
A6: 5 | B6: Shonta | C6: Hedrick | D6: Miss | E6: fem | F6: 60 | G6: Beechdale Road | H6: Port Talbot | I6: 39988 | J6: 44 | K6: C3 | L6: =COUNTBLANK(Portfolio43[[#This Row],[ID]:[Product]]) -> 0
A7: 6 | B7: Veronika | C7: Lundy | D7: Miss | E7: F | F7: 90 | G7: Katherine Gardens | H7: Ardgay | I7: 40316 | J7: 37 | K7: A3 | L7: =COUNTBLANK(Portfolio43[[#This Row],[ID]:[Product]]) -> 0 | N7: Added a new column named "Blanks" to identify the number of blank cells in each row by Using COUNTBLANK Function
A8: 7 | B8: Valeria | C8: Frost | D8: Mrs | E8: F | F8: 30 | G8: Ross Way | H8: Solihull | I8: 40202 | J8: 12 | K8: C2 | L8: =COUNTBLANK(Portfolio43[[#This Row],[ID]:[Product]]) -> 0
A9: 8 | B9: Randa | C9: Woods | D9: Mrs | E9: F | F9: 30 | G9: Artisans Dwellings | H9: Tring | I9: 40497 | J9: 55 | K9: C1 | L9: =COUNTBLANK(Portfolio43[[#This Row],[ID]:[Product]]) -> 0 | N9: Formula: | P9: COUNTBLANK(Portfolio43[@[ID]:[Product]])
A10: 9 | B10: Karole | C10: Navarro | D10: Mrs | E10: F | F10: 30 | G10: Rhoda Street | H10: St. Ives | I10: 39938 | J10: 10 | K10: C3 | L10: =COUNTBLANK(Portfolio43[[#This Row],[ID]:[Product]]) -> 0
A11: 10 | B11: Martin | C11: Anthony | D11: Miss | E11: F | F11: 90 | G11: Iceland Road | H11: Campbeltown | I11: 40466 | J11: 76 | K11: A2 | L11: =COUNTBLANK(Portfolio43[[#This Row],[ID]:[Product]]) -> 0 | N11: Used COUNTIF function to count the number of rows containing values greater than 0 in the Blanks column
A12: 11 | B12: Shanae | C12: Roland | D12: Mrs | E12: F | F12: 90 | G12: Samels Court | H12: Newbridge | I12: 40031 | J12: 28 | K12: C2 | L12: =COUNTBLANK(Portfolio43[[#This Row],[ID]:[Product]]) -> 0
A13: 12 | B13: Yen | C13: Culver | D13: Miss | E13: F | F13: 60 | G13: Garratt Green | H13: London | I13: 39965 | J13: 41 | K13: A2 | L13: =COUNTBLANK(Portfolio43[[#This Row],[ID]:[Product]]) -> 0 | N13: Formula: | P13: COUNTIF(L2:L2001,">0")
A14: 13 | B14: Monica | C14: Doran | D14: Miss | E14: F | F14: 90 | G14: High St | H14: Caldicot | I14: 39516 | J14: 48 | K14: B | L14: =COUNTBLANK(Portfolio43[[#This Row],[ID]:[Product]]) -> 0 | N14: Count | P14: =COUNTIF(Portfolio43[Blanks],">0") -> 14
A15: 14 | B15: Laureen | C15: Richards | D15: Prof | E15: F | F15: 90 | G15: Brackenfield Close | H15: Broseley | I15: 39665 | J15: 34 | K15: C4 | L15: =COUNTBLANK(Portfolio43[[#This Row],[ID]:[Product]]) -> 0
A16: 15 | B16: Meta | C16: Wright | D16: Mrs | E16: F | F16: 60 | G16: Bearstead Rise | H16: Y Felinheli | I16: 40337 | J16: 57 | K16: C4 | L16: =COUNTBLANK(Portfolio43[[#This Row],[ID]:[Product]]) -> 0 | N16: Using the Filter Option in the Blanks column we selected the values greater than 0 and deleted them
A17: 16 | B17: Bobbye | C17: Vasquez | D17: Mrs | E17: F | F17: 30 | G17: Baker Road | H17: Trowbridge | I17: 40532 | J17: 59 | K17: E | L17: =COUNTBLANK(Portfolio43[[#This Row],[ID]:[Product]]) -> 0
A18: 17 | B18: Emily | C18: Butler | D18: Miss | E18: F | F18: 30 | G18: Telford Close | H18: Isles Of Scilly | I18: 40271 | J18: 84 | K18: C1 | L18: =COUNTBLANK(Portfolio43[[#This Row],[ID]:[Product]]) -> 0
A19: 18 | B19: Iona | C19: Hutchinson | D19: Ms | E19: F | F19: 30 | G19: Queens Buildings | H19: Kilmacolm | I19: 40183 | J19: 39 | K19: C4 | L19: =COUNTBLANK(Portfolio43[[#This Row],[ID]:[Product]]) -> 0 | N19: Note: This Sheet is Password Protected, To unlock this sheet use "qwer" as password
A20: 19 | B20: Windy | C20: Cabrera | D20: Miss | E20: F | F20: 90 | G20: Havelock Cottages | H20: Bridgwater | I20: 40381 | J20: 54 | K20: A1 | L20: =COUNTBLANK(Portfolio43[[#This Row],[ID]:[Product]]) -> 0
A21: 20 | B21: Cherry | C21: Walsh | D21: Mrs | E21: F | F21: 90 | G21: Huntingdon Gardens | H21: Essex | I21: 40469 | J21: 33 | K21: C2 | L21: =COUNTBLANK(Portfolio43[[#This Row],[ID]:[Product]]) -> 0
A22: 21 | B22: Jaye | C22: FARLEY | D22: Mrs | E22: F | F22: 60 | G22: Embankment Gardens | H22: Badminton | I22: 39587 | J22: 84 | K22: C2 | L22: =COUNTBLANK(Portfolio43[[#This Row],[ID]:[Product]]) -> 0
A23: 22 | B23: Garnet | C23: Tipton | D23: Miss | E23: F | F23: 30 | G23: Burton Grove | H23: Halesowen | I23: 39993 | J23: 94 | K23: C1 | L23: =COUNTBLANK(Portfolio43[[#This Row],[ID]:[Product]]) -> 0
A24: 23 | B24: Coral | C24: Grace | D24: Miss | E24: F | F24: 90 | G24: Alliance Road | H24: Kyle | I24: 40470 | J24: 84 | K24: A1 | L24: =COUNTBLANK(Portfolio43[[#This Row],[ID]:[Product]]) -> 0
A25: 24 | B25: Kacy | C25: Ragland | D25: Miss | E25: F | F25: 90 | G25: Coningsby Cottages | H25: Cradley Heath | I25: 40052 | J25: 37 | K25: A3 | L25: =COUNTBLANK(Portfolio43[[#This Row],[ID]:[Product]]) -> 0
A26: 25 | B26: Riva | C26: Crosby | D26: Miss | E26: F | F26: 60 | G26: Burdett Place | H26: Frizington | I26: 40006 | J26: 3 | K26: C2 | L26: =COUNTBLANK(Portfolio43[[#This Row],[ID]:[Product]]) -> 0
A27: 26 | B27: Thi | C27: Stroud | D27: Mrs | E27: F | F27: 30 | G27: Biddenden Way | H27: Longfield | I27: 39893 | J27: 34 | K27: C1 | L27: =COUNTBLANK(Portfolio43[[#This Row],[ID]:[Product]]) -> 0
A28: 27 | B28: Ji | C28: Austin | D28: Mrs | E28: F | F28: 30 | G28: Selhurst Road | H28: Downham Market | I28: 40308 | J28: 78 | K28: A3 | L28: =COUNTBLANK(Portfolio43[[#This Row],[ID]:[Product]]) -> 0
A29: 28 | B29: Molly | C29: MARCUS | D29: Mrs | E29: F | F29: 90 | G29: Lyons Yard | H29: Lyme Regis | I29: 39916 | J29: 46 | K29: A3 | L29: =COUNTBLANK(Portfolio43[[#This Row],[ID]:[Product]]) -> 0
A30: 29 | B30: Alina | C30: Pryor | D30: Ms | E30: F | F30: 90 | G30: Edgar Road | H30: Cornwall | I30: 39906 | J30: 34 | K30: E | L30: =COUNTBLANK(Portfolio43[[#This Row],[ID]:[Product]]) -> 0
A31: 30 | B31: Jo | C31: Simons | D31: Mrs | E31: F | F31: 30 | G31: Roe Lane | H31: Pentre | I31: 39670 | J31: 64 | K31: E | L31: =COUNTBLANK(Portfolio43[[#This Row],[ID]:[Product]]) -> 0
... A95: 94 | B95: Waneta | C95: Klein | D95: Miss | E95: F | F95: 60 | G95: Kidd Place | H95: Strathdon | I95: 39833 | J95: 97 | K95: C3 | L95: =COUNTBLANK(Portfolio43[[#This Row],[ID]:[Product]]) -> 0
A96: 95 | B96: Jadwiga | C96: Contreras | E96: F | F96: 90 | G96: Little Lemon | H96: Llanrwst | I96: 40064 | J96: 24 | K96: E | L96: =COUNTBLANK(Portfolio43[[#This Row],[ID]:[Product]]) -> 1
A97: 96 | B97: Catherina | C97: Galvan | D97: Ms | E97: F | F97: 60 | G97: Little New | H97: Darwen | I97: 39927 | J97: 87 | K97: A2 | L97: =COUNTBLANK(Portfolio43[[#This Row],[ID]:[Product]]) -> 0
A98: 97 | B98: Leslie | C98: Hobson | D98: Mrs | E98: F | F98: 30 | G98: Templecombe Road | H98: Plockton | I98: 40500 | J98: 41 | K98: A2 | L98: =COUNTBLANK(Portfolio43[[#This Row],[ID]:[Product]]) -> 0
A99: 98 | B99: Jona | C99: Mcneill | D99: Miss | E99: F | F99: 90 | G99: Warner Road | H99: Coleford | I99: 40312 | J99: 68 | K99: E | L99: =COUNTBLANK(Portfolio43[[#This Row],[ID]:[Product]]) -> 0
A100: 99 | B100: Phylis | C100: Starks | D100: Mrs | E100: F | F100: 30 | G100: Du Burstow | H100: Surrey | I100: 40037 | J100: 47 | K100: B | L100: =COUNTBLANK(Portfolio43[[#This Row],[ID]:[Product]]) -> 0
A101: 100 | B101: Chasidy | C101: Pittman | D101: Miss | E101: F | F101: 90 | G101: Vine Cottages | H101: Tewkesbury | I101: 40107 | J101: 51 | K101: C1 | L101: =COUNTBLANK(Portfolio43[[#This Row],[ID]:[Product]]) -> 0
A102: 101 | B102: Rina | C102: Hayes | D102: Mrs | E102: F | F102: 60 | G102: Jamaica Level | H102: Buxton | I102: 40000 | J102: 97 | K102: B | L102: =COUNTBLANK(Portfolio43[[#This Row],[ID]:[Product]]) -> 0
A103: 102 | B103: Piedad | C103: Mcmullen | D103: Miss | E103: F | F103: 90 | G103: College Yard | H103: Colchester | I103: 40526 | J103: 70 | K103: C2 | L103: =COUNTBLANK(Portfolio43[[#This Row],[ID]:[Product]]) -> 0
...

Sheet Task 4.1 Deleting Blank Cells
A1: ID | B1: First Name | C1: Last Name | D1: Title | E1: Gender | F1: Credit | G1: Street | H1: Town | I1: Order Date | J1: Quantity | K1: Product | L1: Blanks
A2: 1 | B2: Nanci | C2: Camp | D2: Mrs | E2: F | F2: 60 | G2: Rosmore Road | H2: Berkeley | I2: 39988 | J2: 13 | K2: A1 | L2: =COUNTBLANK(Portfolio434[[#This Row],[ID]:[Product]]) -> 0 | N2: STEPS
A3: 2 | B3: Erlinda | C3: Dorsey | D3: Mrs | E3: F | F3: 90 | G3: Roxwell Road | H3: Glossop | I3: 39770 | J3: 14 | K3: C3 | L3: =COUNTBLANK(Portfolio434[[#This Row],[ID]:[Product]]) -> 0 | N3: The Below values were observed after deleting the blank cells in the Table
A4: 3 | B4: Albertha | C4: Devine | D4: Mrs | E4: F | F4: 60 | G4: Ashbury Place | H4: Immingham | I4: 39895 | J4: 23 | K4: E | L4: =COUNTBLANK(Portfolio434[[#This Row],[ID]:[Product]]) -> 0 | N4: Used COUNTBLANK Function to Identify the total number of Blank Cells in the sheet
A5: 4 | B5: Nathalie | C5: Washington | D5: Miss | E5: F | F5: 60 | G5: Grafton Road | H5: Broadstone | I5: 39830 | J5: 79 | K5: E | L5: =COUNTBLANK(Portfolio434[[#This Row],[ID]:[Product]]) -> 0 | N5: Formula: | P5: COUNTBLANK(Portfolio43)
A6: 5 | B6: Shonta | C6: Hedrick | D6: Miss | E6: fem | F6: 60 | G6: Beechdale Road | H6: Port Talbot | I6: 39988 | J6: 44 | K6: C3 | L6: =COUNTBLANK(Portfolio434[[#This Row],[ID]:[Product]]) -> 0 | N6: Blank cells detected | P6: =COUNTBLANK(Portfolio434[]) -> 0
A7: 6 | B7: Veronika | C7: Lundy | D7: Miss | E7: F | F7: 90 | G7: Katherine Gardens | H7: Ardgay | I7: 40316 | J7: 37 | K7: A3 | L7: =COUNTBLANK(Portfolio434[[#This Row],[ID]:[Product]]) -> 0
A8: 7 | B8: Valeria | C8: Frost | D8: Mrs | E8: F | F8: 30 | G8: Ross Way | H8: Solihull | I8: 40202 | J8: 12 | K8: C2 | L8: =COUNTBLANK(Portfolio434[[#This Row],[ID]:[Product]]) -> 0 | N8: Added a new column named "Blanks" to identify the number of blank cells in each row by Using COUNTBLANK Function
A9: 8 | B9: Randa | C9: Woods | D9: Mrs | E9: F | F9: 30 | G9: Artisans Dwellings | H9: Tring | I9: 40497 | J9: 55 | K9: C1 | L9: =COUNTBLANK(Portfolio434[[#This Row],[ID]:[Product]]) -> 0
A10: 9 | B10: Karole | C10: Navarro | D10: Mrs | E10: F | F10: 30 | G10: Rhoda Street | H10: St. Ives | I10: 39938 | J10: 10 | K10: C3 | L10: =COUNTBLANK(Portfolio434[[#This Row],[ID]:[Product]]) -> 0 | N10: Formula: | P10: COUNTBLANK(Portfolio43[@[ID]:[Product]])
A11: 10 | B11: Martin | C11: Anthony | D11: Miss | E11: F | F11: 90 | G11: Iceland Road | H11: Campbeltown | I11: 40466 | J11: 76 | K11: A2 | L11: =COUNTBLANK(Portfolio434[[#This Row],[ID]:[Product]]) -> 0
A12: 11 | B12: Shanae | C12: Roland | D12: Mrs | E12: F | F12: 90 | G12: Samels Court | H12: Newbridge | I12: 40031 | J12: 28 | K12: C2 | L12: =COUNTBLANK(Portfolio434[[#This Row],[ID]:[Product]]) -> 0 | N12: Used COUNTIF function to count the number of rows containing values greater than 0 in the Blanks column
A13: 12 | B13: Yen | C13: Culver | D13: Miss | E13: F | F13: 60 | G13: Garratt Green | H13: London | I13: 39965 | J13: 41 | K13: A2 | L13: =COUNTBLANK(Portfolio434[[#This Row],[ID]:[Product]]) -> 0
A14: 13 | B14: Monica | C14: Doran | D14: Miss | E14: F | F14: 90 | G14: High St | H14: Caldicot | I14: 39516 | J14: 48 | K14: B | L14: =COUNTBLANK(Portfolio434[[#This Row],[ID]:[Product]]) -> 0 | N14: Formula: | P14: COUNTIF(L2:L2001,">0")
A15: 14 | B15: Laureen | C15: Richards | D15: Prof | E15: F | F15: 90 | G15: Brackenfield Close | H15: Broseley | I15: 39665 | J15: 34 | K15: C4 | L15: =COUNTBLANK(Portfolio434[[#This Row],[ID]:[Product]]) -> 0 | N15: Count | P15: =COUNTIF(Portfolio434[Blanks],">0") -> 0
A16: 15 | B16: Meta | C16: Wright | D16: Mrs | E16: F | F16: 60 | G16: Bearstead Rise | H16: Y Felinheli | I16: 40337 | J16: 57 | K16: C4 | L16: =COUNTBLANK(Portfolio434[[#This Row],[ID]:[Product]]) -> 0
A17: 16 | B17: Bobbye | C17: Vasquez | D17: Mrs | E17: F | F17: 30 | G17: Baker Road | H17: Trowbridge | I17: 40532 | J17: 59 | K17: E | L17: =COUNTBLANK(Portfolio434[[#This Row],[ID]:[Product]]) -> 0 | N17: The remaining values were identifyed using the SUBTOTAL function
A18: 17 | B18: Emily | C18: Butler | D18: Miss | E18: F | F18: 30 | G18: Telford Close | H18: Isles Of Scilly | I18: 40271 | J18: 84 | K18: C1 | L18: =COUNTBLANK(Portfolio434[[#This Row],[ID]:[Product]]) -> 0 | N18: Formula : =SUBTOTAL(3,A2:A1987)
A19: 18 | B19: Iona | C19: Hutchinson | D19: Ms | E19: F | F19: 30 | G19: Queens Buildings | H19: Kilmacolm | I19: 40183 | J19: 39 | K19: C4 | L19: =COUNTBLANK(Portfolio434[[#This Row],[ID]:[Product]]) -> 0 | N19: Blank rows deleted | P19: =2000-P20 -> 14
A20: 19 | B20: Windy | C20: Cabrera | D20: Miss | E20: F | F20: 90 | G20: Havelock Cottages | H20: Bridgwater | I20: 40381 | J20: 54 | K20: A1 | L20: =COUNTBLANK(Portfolio434[[#This Row],[ID]:[Product]]) -> 0 | N20: Values | P20: =SUBTOTAL(3,A2:A1987) -> 1986
A21: 20 | B21: Cherry | C21: Walsh | D21: Mrs | E21: F | F21: 90 | G21: Huntingdon Gardens | H21: Essex | I21: 40469 | J21: 33 | K21: C2 | L21: =COUNTBLANK(Portfolio434[[#This Row],[ID]:[Product]]) -> 0
A22: 21 | B22: Jaye | C22: FARLEY | D22: Mrs | E22: F | F22: 60 | G22: Embankment Gardens | H22: Badminton | I22: 39587 | J22: 84 | K22: C2 | L22: =COUNTBLANK(Portfolio434[[#This Row],[ID]:[Product]]) -> 0 | N22: Note: This Sheet is Password Protected, To unlock this sheet use "qwer" as password
A23: 22 | B23: Garnet | C23: Tipton | D23: Miss | E23: F | F23: 30 | G23: Burton Grove | H23: Halesowen | I23: 39993 | J23: 94 | K23: C1 | L23: =COUNTBLANK(Portfolio434[[#This Row],[ID]:[Product]]) -> 0
A24: 23 | B24: Coral | C24: Grace | D24: Miss | E24: F | F24: 90 | G24: Alliance Road | H24: Kyle | I24: 40470 | J24: 84 | K24: A1 | L24: =COUNTBLANK(Portfolio434[[#This Row],[ID]:[Product]]) -> 0
A25: 24 | B25: Kacy | C25: Ragland | D25: Miss | E25: F | F25: 90 | G25: Coningsby Cottages | H25: Cradley Heath | I25: 40052 | J25: 37 | K25: A3 | L25: =COUNTBLANK(Portfolio434[[#This Row],[ID]:[Product]]) -> 0
A26: 25 | B26: Riva | C26: Crosby | D26: Miss | E26: F | F26: 60 | G26: Burdett Place | H26: Frizington | I26: 40006 | J26: 3 | K26: C2 | L26: =COUNTBLANK(Portfolio434[[#This Row],[ID]:[Product]]) -> 0
A27: 26 | B27: Thi | C27: Stroud | D27: Mrs | E27: F | F27: 30 | G27: Biddenden Way | H27: Longfield | I27: 39893 | J27: 34 | K27: C1 | L27: =COUNTBLANK(Portfolio434[[#This Row],[ID]:[Product]]) -> 0
A28: 27 | B28: Ji | C28: Austin | D28: Mrs | E28: F | F28: 30 | G28: Selhurst Road | H28: Downham Market | I28: 40308 | J28: 78 | K28: A3 | L28: =COUNTBLANK(Portfolio434[[#This Row],[ID]:[Product]]) -> 0
A29: 28 | B29: Molly | C29: MARCUS | D29: Mrs | E29: F | F29: 90 | G29: Lyons Yard | H29: Lyme Regis | I29: 39916 | J29: 46 | K29: A3 | L29: =COUNTBLANK(Portfolio434[[#This Row],[ID]:[Product]]) -> 0
A30: 29 | B30: Alina | C30: Pryor | D30: Ms | E30: F | F30: 90 | G30: Edgar Road | H30: Cornwall | I30: 39906 | J30: 34 | K30: E | L30: =COUNTBLANK(Portfolio434[[#This Row],[ID]:[Product]]) -> 0
A31: 30 | B31: Jo | C31: Simons | D31: Mrs | E31: F | F31: 30 | G31: Roe Lane | H31: Pentre | I31: 39670 | J31: 64 | K31: E | L31: =COUNTBLANK(Portfolio434[[#This Row],[ID]:[Product]]) -> 0
A32: 31 | B32: Lacy | C32: Emerson | D32: Miss | E32: F | F32: 90 | G32: Beaufort Wharf | H32: Cirencester | I32: 39552 | J32: 80 | K32: D | L32: =COUNTBLANK(Portfolio434[[#This Row],[ID]:[Product]]) -> 0
A33: 32 | B33: Janice | C33: Oneal | D33: Miss | E33: F | F33: 60 | G33: Anns Close | H33: Ellesmere | I33: 40508 | J33: 88 | K33: B | L33: =COUNTBLANK(Portfolio434[[#This Row],[ID]:[Product]]) -> 0
A34: 33 | B34: Donella | C34: Fenton | D34: Miss | E34: F | F34: 90 | G34: Sladedale Road | H34: Newnham | I34: 39534 | J34: 60 | K34: E | L34: =COUNTBLANK(Portfolio434[[#This Row],[ID]:[Product]]) -> 0
... A1987: 2000 | B1987: Gaston | C1987: Guy | D1987: Mr | E1987: M | F1987: 60 | G1987: Wansbeck Road | H1987: Ledbury | I1987: 40301 | J1987: 58 | K1987: D | L1987: =COUNTBLANK(Portfolio434[[#This Row],[ID]:[Product]]) -> 0

Sheet Task 4.2
A1: ID | B1: First Name | C1: Last Name | D1: Title | E1: Gender | F1: Credit | G1: Street | H1: Town | I1: Order Date | J1: Quantity | K1: Product | M1: Last Name Correction | N1: Records Affected | O1: Gender Correction | P1: Records Affected2 | Q1: Initials
A2: 1 | B2: Nanci | C2: Camp | D2: Mrs | E2: F | F2: 60 | G2: Rosmore Road | H2: Berkeley | I2: 39988 | J2: 13 | K2: A1 | M2: =PROPER(Portfolio4346[[#This Row],[Last Name]]) -> Camp | N2: =IF(EXACT(C2,M2)=TRUE, "-", "Corrected to Title Case") -> - | O2: =IF(LEFT(E2,1)="f","F","M") -> F | P2: =IF(EXACT(E2,O2)=TRUE,"-","Corrected Errors") -> - | Q2: =UPPER(LEFT(B2,1)) -> N | S2: STEPS
A3: 2 | B3: Erlinda | C3: Dorsey | D3: Mrs | E3: F | F3: 90 | G3: Roxwell Road | H3: Glossop | I3: 39770 | J3: 14 | K3: C3 | M3: =PROPER(Portfolio4346[[#This Row],[Last Name]]) -> Dorsey | N3: =IF(EXACT(C3,M3)=TRUE, "-", "Corrected to Title Case") -> - | O3: =IF(LEFT(E3,1)="f","F","M") -> F | P3: =IF(EXACT(E3,O3)=TRUE,"-","Corrected Errors") -> - | Q3: =UPPER(LEFT(B3,1)) -> E | S3: 1. Created a new column named "Last Name Correction"
A4: 3 | B4: Albertha | C4: Devine | D4: Mrs | E4: F | F4: 60 | G4: Ashbury Place | H4: Immingham | I4: 39895 | J4: 23 | K4: E | M4: =PROPER(Portfolio4346[[#This Row],[Last Name]]) -> Devine | N4: =IF(EXACT(C4,M4)=TRUE, "-", "Corrected to Title Case") -> - | O4: =IF(LEFT(E4,1)="f","F","M") -> F | P4: =IF(EXACT(E4,O4)=TRUE,"-","Corrected Errors") -> - | Q4: =UPPER(LEFT(B4,1)) -> A | S4: Used the PROPER function to change the Last Name from Upper Case to Title Case
A5: 4 | B5: Nathalie | C5: Washington | D5: Miss | E5: F | F5: 60 | G5: Grafton Road | H5: Broadstone | I5: 39830 | J5: 79 | K5: E | M5: =PROPER(Portfolio4346[[#This Row],[Last Name]]) -> Washington | N5: =IF(EXACT(C5,M5)=TRUE, "-", "Corrected to Title Case") -> - | O5: =IF(LEFT(E5,1)="f","F","M") -> F | P5: =IF(EXACT(E5,O5)=TRUE,"-","Corrected Errors") -> - | Q5: =UPPER(LEFT(B5,1)) -> N | S5: Formula: =PROPER(Portfolio4346[@[Last Name]])
A6: 5 | B6: Shonta | C6: Hedrick | D6: Miss | E6: fem | F6: 60 | G6: Beechdale Road | H6: Port Talbot | I6: 39988 | J6: 44 | K6: C3 | M6: =PROPER(Portfolio4346[[#This Row],[Last Name]]) -> Hedrick | N6: =IF(EXACT(C6,M6)=TRUE, "-", "Corrected to Title Case") -> - | O6: =IF(LEFT(E6,1)="f","F","M") -> F | P6: =IF(EXACT(E6,O6)=TRUE,"-","Corrected Errors") -> Corrected Errors | Q6: =UPPER(LEFT(B6,1)) -> S
A7: 6 | B7: Veronika | C7: Lundy | D7: Miss | E7: F | F7: 90 | G7: Katherine Gardens | H7: Ardgay | I7: 40316 | J7: 37 | K7: A3 | M7: =PROPER(Portfolio4346[[#This Row],[Last Name]]) -> Lundy | N7: =IF(EXACT(C7,M7)=TRUE, "-", "Corrected to Title Case") -> - | O7: =IF(LEFT(E7,1)="f","F","M") -> F | P7: =IF(EXACT(E7,O7)=TRUE,"-","Corrected Errors") -> - | Q7: =UPPER(LEFT(B7,1)) -> V | S7: To calculate the number of records affected we used IF & EXACT function
A8: 7 | B8: Valeria | C8: Frost | D8: Mrs | E8: F | F8: 30 | G8: Ross Way | H8: Solihull | I8: 40202 | J8: 12 | K8: C2 | M8: =PROPER(Portfolio4346[[#This Row],[Last Name]]) -> Frost | N8: =IF(EXACT(C8,M8)=TRUE, "-", "Corrected to Title Case") -> - | O8: =IF(LEFT(E8,1)="f","F","M") -> F | P8: =IF(EXACT(E8,O8)=TRUE,"-","Corrected Errors") -> - | Q8: =UPPER(LEFT(B8,1)) -> V | S8: Formula: =IF(EXACT(C2,M2)=TRUE, "-", "Corrected to Title Case")
A9: 8 | B9: Randa | C9: Woods | D9: Mrs | E9: F | F9: 30 | G9: Artisans Dwellings | H9: Tring | I9: 40497 | J9: 55 | K9: C1 | M9: =PROPER(Portfolio4346[[#This Row],[Last Name]]) -> Woods | N9: =IF(EXACT(C9,M9)=TRUE, "-", "Corrected to Title Case") -> - | O9: =IF(LEFT(E9,1)="f","F","M") -> F | P9: =IF(EXACT(E9,O9)=TRUE,"-","Corrected Errors") -> - | Q9: =UPPER(LEFT(B9,1)) -> R
A10: 9 | B10: Karole | C10: Navarro | D10: Mrs | E10: F | F10: 30 | G10: Rhoda Street | H10: St. Ives | I10: 39938 | J10: 10 | K10: C3 | M10: =PROPER(Portfolio4346[[#This Row],[Last Name]]) -> Navarro | N10: =IF(EXACT(C10,M10)=TRUE, "-", "Corrected to Title Case") -> - | O10: =IF(LEFT(E10,1)="f","F","M") -> F | P10: =IF(EXACT(E10,O10)=TRUE,"-","Corrected Errors") -> - | Q10: =UPPER(LEFT(B10,1)) -> K | S10: Then we count the number of records affected using COUNTIF function
A11: 10 | B11: Martin | C11: Anthony | D11: Miss | E11: F | F11: 90 | G11: Iceland Road | H11: Campbeltown | I11: 40466 | J11: 76 | K11: A2 | M11: =PROPER(Portfolio4346[[#This Row],[Last Name]]) -> Anthony | N11: =IF(EXACT(C11,M11)=TRUE, "-", "Corrected to Title Case") -> - | O11: =IF(LEFT(E11,1)="f","F","M") -> F | P11: =IF(EXACT(E11,O11)=TRUE,"-","Corrected Errors") -> - | Q11: =UPPER(LEFT(B11,1)) -> M | S11: Count of Affected records | U11: =COUNTIF(Table6[Records Affected],"Corrected to Title Case") -> 11
A12: 11 | B12: Shanae | C12: Roland | D12: Mrs | E12: F | F12: 90 | G12: Samels Court | H12: Newbridge | I12: 40031 | J12: 28 | K12: C2 | M12: =PROPER(Portfolio4346[[#This Row],[Last Name]]) -> Roland | N12: =IF(EXACT(C12,M12)=TRUE, "-", "Corrected to Title Case") -> - | O12: =IF(LEFT(E12,1)="f","F","M") -> F | P12: =IF(EXACT(E12,O12)=TRUE,"-","Corrected Errors") -> - | Q12: =UPPER(LEFT(B12,1)) -> S
A13: 12 | B13: Yen | C13: Culver | D13: Miss | E13: F | F13: 60 | G13: Garratt Green | H13: London | I13: 39965 | J13: 41 | K13: A2 | M13: =PROPER(Portfolio4346[[#This Row],[Last Name]]) -> Culver | N13: =IF(EXACT(C13,M13)=TRUE, "-", "Corrected to Title Case") -> - | O13: =IF(LEFT(E13,1)="f","F","M") -> F | P13: =IF(EXACT(E13,O13)=TRUE,"-","Corrected Errors") -> - | Q13: =UPPER(LEFT(B13,1)) -> Y
A14: 13 | B14: Monica | C14: Doran | D14: Miss | E14: F | F14: 90 | G14: High St | H14: Caldicot | I14: 39516 | J14: 48 | K14: B | M14: =PROPER(Portfolio4346[[#This Row],[Last Name]]) -> Doran | N14: =IF(EXACT(C14,M14)=TRUE, "-", "Corrected to Title Case") -> - | O14: =IF(LEFT(E14,1)="f","F","M") -> F | P14: =IF(EXACT(E14,O14)=TRUE,"-","Corrected Errors") -> - | Q14: =UPPER(LEFT(B14,1)) -> M | S14: 2. Created one more column for "Gender Correction"
A15: 14 | B15: Laureen | C15: Richards | D15: Prof | E15: F | F15: 90 | G15: Brackenfield Close | H15: Broseley | I15: 39665 | J15: 34 | K15: C4 | M15: =PROPER(Portfolio4346[[#This Row],[Last Name]]) -> Richards | N15: =IF(EXACT(C15,M15)=TRUE, "-", "Corrected to Title Case") -> - | O15: =IF(LEFT(E15,1)="f","F","M") -> F | P15: =IF(EXACT(E15,O15)=TRUE,"-","Corrected Errors") -> - | Q15: =UPPER(LEFT(B15,1)) -> L | S15: Used IF & LEFT function to correct the errors in Gender column
A16: 15 | B16: Meta | C16: Wright | D16: Mrs | E16: F | F16: 60 | G16: Bearstead Rise | H16: Y Felinheli | I16: 40337 | J16: 57 | K16: C4 | M16: =PROPER(Portfolio4346[[#This Row],[Last Name]]) -> Wright | N16: =IF(EXACT(C16,M16)=TRUE, "-", "Corrected to Title Case") -> - | O16: =IF(LEFT(E16,1)="f","F","M") -> F | P16: =IF(EXACT(E16,O16)=TRUE,"-","Corrected Errors") -> - | Q16: =UPPER(LEFT(B16,1)) -> M | S16: Formula: =IF(LEFT(E3,1)="f","F","M")
A17: 16 | B17: Bobbye | C17: Vasquez | D17: Mrs | E17: F | F17: 30 | G17: Baker Road | H17: Trowbridge | I17: 40532 | J17: 59 | K17: E | M17: =PROPER(Portfolio4346[[#This Row],[Last Name]]) -> Vasquez | N17: =IF(EXACT(C17,M17)=TRUE, "-", "Corrected to Title Case") -> - | O17: =IF(LEFT(E17,1)="f","F","M") -> F | P17: =IF(EXACT(E17,O17)=TRUE,"-","Corrected Errors") -> - | Q17: =UPPER(LEFT(B17,1)) -> B
A18: 17 | B18: Emily | C18: Butler | D18: Miss | E18: F | F18: 30 | G18: Telford Close | H18: Isles Of Scilly | I18: 40271 | J18: 84 | K18: C1 | M18: =PROPER(Portfolio4346[[#This Row],[Last Name]]) -> Butler | N18: =IF(EXACT(C18,M18)=TRUE, "-", "Corrected to Title Case") -> - | O18: =IF(LEFT(E18,1)="f","F","M") -> F | P18: =IF(EXACT(E18,O18)=TRUE,"-","Corrected Errors") -> - | Q18: =UPPER(LEFT(B18,1)) -> E | S18: Again to calculate the number of records affected we used IF & EXACT function
A19: 18 | B19: Iona | C19: Hutchinson | D19: Ms | E19: F | F19: 30 | G19: Queens Buildings | H19: Kilmacolm | I19: 40183 | J19: 39 | K19: C4 | M19: =PROPER(Portfolio4346[[#This Row],[Last Name]]) -> Hutchinson | N19: =IF(EXACT(C19,M19)=TRUE, "-", "Corrected to Title Case") -> - | O19: =IF(LEFT(E19,1)="f","F","M") -> F | P19: =IF(EXACT(E19,O19)=TRUE,"-","Corrected Errors") -> - | Q19: =UPPER(LEFT(B19,1)) -> I | S19: Formula: =IF(EXACT(E3,O3)=TRUE,"-","Corrected Errors")
A20: 19 | B20: Windy | C20: Cabrera | D20: Miss | E20: F | F20: 90 | G20: Havelock Cottages | H20: Bridgwater | I20: 40381 | J20: 54 | K20: A1 | M20: =PROPER(Portfolio4346[[#This Row],[Last Name]]) -> Cabrera | N20: =IF(EXACT(C20,M20)=TRUE, "-", "Corrected to Title Case") -> - | O20: =IF(LEFT(E20,1)="f","F","M") -> F | P20: =IF(EXACT(E20,O20)=TRUE,"-","Corrected Errors") -> - | Q20: =UPPER(LEFT(B20,1)) -> W
A21: 20 | B21: Cherry | C21: Walsh | D21: Mrs | E21: F | F21: 90 | G21: Huntingdon Gardens | H21: Essex | I21: 40469 | J21: 33 | K21: C2 | M21: =PROPER(Portfolio4346[[#This Row],[Last Name]]) -> Walsh | N21: =IF(EXACT(C21,M21)=TRUE, "-", "Corrected to Title Case") -> - | O21: =IF(LEFT(E21,1)="f","F","M") -> F | P21: =IF(EXACT(E21,O21)=TRUE,"-","Corrected Errors") -> - | Q21: =UPPER(LEFT(B21,1)) -> C | S21: Then we count the number of Records affected using COUNTIF function
A22: 21 | B22: Jaye | C22: FARLEY | D22: Mrs | E22: F | F22: 60 | G22: Embankment Gardens | H22: Badminton | I22: 39587 | J22: 84 | K22: C2 | M22: =PROPER(Portfolio4346[[#This Row],[Last Name]]) -> Farley | N22: =IF(EXACT(C22,M22)=TRUE, "-", "Corrected to Title Case") -> Corrected to Title Case | O22: =IF(LEFT(E22,1)="f","F","M") -> F | P22: =IF(EXACT(E22,O22)=TRUE,"-","Corrected Errors") -> - | Q22: =UPPER(LEFT(B22,1)) -> J | S22: Count of Affected records | U22: =COUNTIF(Table6[Records Affected2],"Corrected Errors") -> 35
A23: 22 | B23: Garnet | C23: Tipton | D23: Miss | E23: F | F23: 30 | G23: Burton Grove | H23: Halesowen | I23: 39993 | J23: 94 | K23: C1 | M23: =PROPER(Portfolio4346[[#This Row],[Last Name]]) -> Tipton | N23: =IF(EXACT(C23,M23)=TRUE, "-", "Corrected to Title Case") -> - | O23: =IF(LEFT(E23,1)="f","F","M") -> F | P23: =IF(EXACT(E23,O23)=TRUE,"-","Corrected Errors") -> - | Q23: =UPPER(LEFT(B23,1)) -> G
A24: 23 | B24: Coral | C24: Grace | D24: Miss | E24: F | F24: 90 | G24: Alliance Road | H24: Kyle | I24: 40470 | J24: 84 | K24: A1 | M24: =PROPER(Portfolio4346[[#This Row],[Last Name]]) -> Grace | N24: =IF(EXACT(C24,M24)=TRUE, "-", "Corrected to Title Case") -> - | O24: =IF(LEFT(E24,1)="f","F","M") -> F | P24: =IF(EXACT(E24,O24)=TRUE,"-","Corrected Errors") -> - | Q24: =UPPER(LEFT(B24,1)) -> C
A25: 24 | B25: Kacy | C25: Ragland | D25: Miss | E25: F | F25: 90 | G25: Coningsby Cottages | H25: Cradley Heath | I25: 40052 | J25: 37 | K25: A3 | M25: =PROPER(Portfolio4346[[#This Row],[Last Name]]) -> Ragland | N25: =IF(EXACT(C25,M25)=TRUE, "-", "Corrected to Title Case") -> - | O25: =IF(LEFT(E25,1)="f","F","M") -> F | P25: =IF(EXACT(E25,O25)=TRUE,"-","Corrected Errors") -> - | Q25: =UPPER(LEFT(B25,1)) -> K | S25: 3. Added one more column to show "Initials"
A26: 25 | B26: Riva | C26: Crosby | D26: Miss | E26: F | F26: 60 | G26: Burdett Place | H26: Frizington | I26: 40006 | J26: 3 | K26: C2 | M26: =PROPER(Portfolio4346[[#This Row],[Last Name]]) -> Crosby | N26: =IF(EXACT(C26,M26)=TRUE, "-", "Corrected to Title Case") -> - | O26: =IF(LEFT(E26,1)="f","F","M") -> F | P26: =IF(EXACT(E26,O26)=TRUE,"-","Corrected Errors") -> - | Q26: =UPPER(LEFT(B26,1)) -> R | S26: Used the UPPER & LEFT function to show only Initials in the First name column
A27: 26 | B27: Thi | C27: Stroud | D27: Mrs | E27: F | F27: 30 | G27: Biddenden Way | H27: Longfield | I27: 39893 | J27: 34 | K27: C1 | M27: =PROPER(Portfolio4346[[#This Row],[Last Name]]) -> Stroud | N27: =IF(EXACT(C27,M27)=TRUE, "-", "Corrected to Title Case") -> - | O27: =IF(LEFT(E27,1)="f","F","M") -> F | P27: =IF(EXACT(E27,O27)=TRUE,"-","Corrected Errors") -> - | Q27: =UPPER(LEFT(B27,1)) -> T | S27: Formula: =UPPER(LEFT(B2,1))
A28: 27 | B28: Ji | C28: Austin | D28: Mrs | E28: F | F28: 30 | G28: Selhurst Road | H28: Downham Market | I28: 40308 | J28: 78 | K28: A3 | M28: =PROPER(Portfolio4346[[#This Row],[Last Name]]) -> Austin | N28: =IF(EXACT(C28,M28)=TRUE, "-", "Corrected to Title Case") -> - | O28: =IF(LEFT(E28,1)="f","F","M") -> F | P28: =IF(EXACT(E28,O28)=TRUE,"-","Corrected Errors") -> - | Q28: =UPPER(LEFT(B28,1)) -> J
A29: 28 | B29: Molly | C29: MARCUS | D29: Mrs | E29: F | F29: 90 | G29: Lyons Yard | H29: Lyme Regis | I29: 39916 | J29: 46 | K29: A3 | M29: =PROPER(Portfolio4346[[#This Row],[Last Name]]) -> Marcus | N29: =IF(EXACT(C29,M29)=TRUE, "-", "Corrected to Title Case") -> Corrected to Title Case | O29: =IF(LEFT(E29,1)="f","F","M") -> F | P29: =IF(EXACT(E29,O29)=TRUE,"-","Corrected Errors") -> - | Q29: =UPPER(LEFT(B29,1)) -> M | S29: Note: This Sheet is Password Protected, To unlock this sheet use "qwer" as password
A30: 29 | B30: Alina | C30: Pryor | D30: Ms | E30: F | F30: 90 | G30: Edgar Road | H30: Cornwall | I30: 39906 | J30: 34 | K30: E | M30: =PROPER(Portfolio4346[[#This Row],[Last Name]]) -> Pryor | N30: =IF(EXACT(C30,M30)=TRUE, "-", "Corrected to Title Case") -> - | O30: =IF(LEFT(E30,1)="f","F","M") -> F | P30: =IF(EXACT(E30,O30)=TRUE,"-","Corrected Errors") -> - | Q30: =UPPER(LEFT(B30,1)) -> A
A31: 30 | B31: Jo | C31: Simons | D31: Mrs | E31: F | F31: 30 | G31: Roe Lane | H31: Pentre | I31: 39670 | J31: 64 | K31: E | M31: =PROPER(Portfolio4346[[#This Row],[Last Name]]) -> Simons | N31: =IF(EXACT(C31,M31)=TRUE, "-", "Corrected to Title Case") -> - | O31: =IF(LEFT(E31,1)="f","F","M") -> F | P31: =IF(EXACT(E31,O31)=TRUE,"-","Corrected Errors") -> - | Q31: =UPPER(LEFT(B31,1)) -> J
A32: 31 | B32: Lacy | C32: Emerson | D32: Miss | E32: F | F32: 90 | G32: Beaufort Wharf | H32: Cirencester | I32: 39552 | J32: 80 | K32: D | M32: =PROPER(Portfolio4346[[#This Row],[Last Name]]) -> Emerson | N32: =IF(EXACT(C32,M32)=TRUE, "-", "Corrected to Title Case") -> - | O32: =IF(LEFT(E32,1)="f","F","M") -> F | P32: =IF(EXACT(E32,O32)=TRUE,"-","Corrected Errors") -> - | Q32: =UPPER(LEFT(B32,1)) -> L
A33: 32 | B33: Janice | C33: Oneal | D33: Miss | E33: F | F33: 60 | G33: Anns Close | H33: Ellesmere | I33: 40508 | J33: 88 | K33: B | M33: =PROPER(Portfolio4346[[#This Row],[Last Name]]) -> Oneal | N33: =IF(EXACT(C33,M33)=TRUE, "-", "Corrected to Title Case") -> - | O33: =IF(LEFT(E33,1)="f","F","M") -> F | P33: =IF(EXACT(E33,O33)=TRUE,"-","Corrected Errors") -> - | Q33: =UPPER(LEFT(B33,1)) -> J
A34: 33 | B34: Donella | C34: Fenton | D34: Miss | E34: F | F34: 90 | G34: Sladedale Road | H34: Newnham | I34: 39534 | J34: 60 | K34: E | M34: =PROPER(Portfolio4346[[#This Row],[Last Name]]) -> Fenton | N34: =IF(EXACT(C34,M34)=TRUE, "-", "Corrected to Title Case") -> - | O34: =IF(LEFT(E34,1)="f","F","M") -> F | P34: =IF(EXACT(E34,O34)=TRUE,"-","Corrected Errors") -> - | Q34: =UPPER(LEFT(B34,1)) -> D
A35: 34 | B35: Jacinta | C35: Blackburn | D35: Mrs | E35: F | F35: 30 | G35: Falkland Place | H35: Ascot | I35: 39746 | J35: 22 | K35: C1 | M35: =PROPER(Portfolio4346[[#This Row],[Last Name]]) -> Blackburn | N35: =IF(EXACT(C35,M35)=TRUE, "-", "Corrected to Title Case") -> - | O35: =IF(LEFT(E35,1)="f","F","M") -> F | P35: =IF(EXACT(E35,O35)=TRUE,"-","Corrected Errors") -> - | Q35: =UPPER(LEFT(B35,1)) -> J
A36: 35 | B36: Chasity | C36: Mcfadden | D36: Miss | E36: F | F36: 60 | G36: Westdean Close | H36: Ardgay | I36: 39449 | J36: 99 | K36: A1 | M36: =PROPER(Portfolio4346[[#This Row],[Last Name]]) -> Mcfadden | N36: =IF(EXACT(C36,M36)=TRUE, "-", "Corrected to Title Case") -> - | O36: =IF(LEFT(E36,1)="f","F","M") -> F | P36: =IF(EXACT(E36,O36)=TRUE,"-","Corrected Errors") -> - | Q36: =UPPER(LEFT(B36,1)) -> C
A37: 36 | B37: Margot | C37: Akers | D37: Miss | E37: F | F37: 30 | G37: Roslyn Avenue | H37: Tidworth | I37: 40442 | J37: 94 | K37: A1 | M37: =PROPER(Portfolio4346[[#This Row],[Last Name]]) -> Akers | N37: =IF(EXACT(C37,M37)=TRUE, "-", "Corrected to Title Case") -> - | O37: =IF(LEFT(E37,1)="f","F","M") -> F | P37: =IF(EXACT(E37,O37)=TRUE,"-","Corrected Errors") -> - | Q37: =UPPER(LEFT(B37,1)) -> M
A38: 37 | B38: Tresa | C38: Meza | D38: Mrs | E38: F | F38: 90 | G38: East Mount | H38: Llandinam | I38: 40452 | J38: 3 | K38: B | M38: =PROPER(Portfolio4346[[#This Row],[Last Name]]) -> Meza | N38: =IF(EXACT(C38,M38)=TRUE, "-", "Corrected to Title Case") -> - | O38: =IF(LEFT(E38,1)="f","F","M") -> F | P38: =IF(EXACT(E38,O38)=TRUE,"-","Corrected Errors") -> - | Q38: =UPPER(LEFT(B38,1)) -> T
A39: 38 | B39: Jack | C39: Johnston | D39: Mrs | E39: F | F39: 60 | G39: Grainger Street | H39: Christchurch | I39: 39530 | J39: 16 | K39: A1 | M39: =PROPER(Portfolio4346[[#This Row],[Last Name]]) -> Johnston | N39: =IF(EXACT(C39,M39)=TRUE, "-", "Corrected to Title Case") -> - | O39: =IF(LEFT(E39,1)="f","F","M") -> F | P39: =IF(EXACT(E39,O39)=TRUE,"-","Corrected Errors") -> - | Q39: =UPPER(LEFT(B39,1)) -> J
A40: 39 | B40: Kaley | C40: Kay | D40: Mrs | E40: F | F40: 90 | G40: Upper Paget | H40: Cheshire | I40: 40098 | J40: 57 | K40: C4 | M40: =PROPER(Portfolio4346[[#This Row],[Last Name]]) -> Kay | N40: =IF(EXACT(C40,M40)=TRUE, "-", "Corrected to Title Case") -> - | O40: =IF(LEFT(E40,1)="f","F","M") -> F | P40: =IF(EXACT(E40,O40)=TRUE,"-","Corrected Errors") -> - | Q40: =UPPER(LEFT(B40,1)) -> K
...

Sheet Task 4.3
A1: ID | B1: First Name | C1: Last Name | D1: Title | E1: Gender | F1: Credit | G1: Street | H1: Town | I1: Order Date | J1: Quantity | K1: Product | L1: Product Name | M1: Order Quantity | N1: Order Value | O1: Year | P1: Month
A2: 1 | B2: =Table6[[#This Row],[Initials]] -> N | C2: =Table6[[#This Row],[Last Name Correction]] -> Camp | D2: Mrs | E2: =Table6[[#This Row],[Gender Correction]] -> F | F2: 60 | G2: Rosmore Road | H2: Berkeley | I2: 39988 | J2: 13 | K2: A1 | L2: =VLOOKUP(Portfolio43468[[#This Row],[Product]],ProductName,2) -> Megawidget S | M2: =VLOOKUP(K2,ProductName,4)*J2 -> 312 | N2: =VLOOKUP(K2,ProductName,3)*M2 -> 246.48 | O2: =YEAR(I2) -> 2009 | P2: =TEXT(I2,"MMM") -> Jun | R2: Lookup Table | X2: STEPS
A3: 2 | B3: =Table6[[#This Row],[Initials]] -> E | C3: =Table6[[#This Row],[Last Name Correction]] -> Dorsey | D3: Mrs | E3: =Table6[[#This Row],[Gender Correction]] -> F | F3: 90 | G3: Roxwell Road | H3: Glossop | I3: 39770 | J3: 14 | K3: C3 | L3: =VLOOKUP(Portfolio43468[[#This Row],[Product]],ProductName,2) -> Ultrathing V3 | M3: =VLOOKUP(K3,ProductName,4)*J3 -> 336 | N3: =VLOOKUP(K3,ProductName,3)*M3 -> 1172.64 | O3: =YEAR(I3) -> 2008 | P3: =TEXT(I3,"MMM") -> Nov | R3: Code | S3: Item | T3: Cost | U3: Case Size | X3: Created a lookup table to calculate Product Name, Order Quantity & Order Value
A4: 3 | B4: =Table6[[#This Row],[Initials]] -> A | C4: =Table6[[#This Row],[Last Name Correction]] -> Devine | D4: Mrs | E4: =Table6[[#This Row],[Gender Correction]] -> F | F4: 60 | G4: Ashbury Place | H4: Immingham | I4: 39895 | J4: 23 | K4: E | L4: =VLOOKUP(Portfolio43468[[#This Row],[Product]],ProductName,2) -> Superwossname | M4: =VLOOKUP(K4,ProductName,4)*J4 -> 460 | N4: =VLOOKUP(K4,ProductName,3)*M4 -> 1430.6 | O4: =YEAR(I4) -> 2009 | P4: =TEXT(I4,"MMM") -> Mar | R4: A1 | S4: Megawidget S | T4: 0.79 | U4: 24 | X4: Formulas Used: | Z4: VLOOKUP([@Product],ProductName,2)
A5: 4 | B5: =Table6[[#This Row],[Initials]] -> N | C5: =Table6[[#This Row],[Last Name Correction]] -> Washington | D5: Miss | E5: =Table6[[#This Row],[Gender Correction]] -> F | F5: 60 | G5: Grafton Road | H5: Broadstone | I5: 39830 | J5: 79 | K5: E | L5: =VLOOKUP(Portfolio43468[[#This Row],[Product]],ProductName,2) -> Superwossname | M5: =VLOOKUP(K5,ProductName,4)*J5 -> 1580 | N5: =VLOOKUP(K5,ProductName,3)*M5 -> 4913.8 | O5: =YEAR(I5) -> 2009 | P5: =TEXT(I5,"MMM") -> Jan | R5: A2 | S5: Megawidget M | T5: 1.19 | U5: 24 | Z5: VLOOKUP(K2,ProductName,4)*J2
A6: 5 | B6: =Table6[[#This Row],[Initials]] -> S | C6: =Table6[[#This Row],[Last Name Correction]] -> Hedrick | D6: Miss | E6: =Table6[[#This Row],[Gender Correction]] -> F | F6: 60 | G6: Beechdale Road | H6: Port Talbot | I6: 39988 | J6: 44 | K6: C3 | L6: =VLOOKUP(Portfolio43468[[#This Row],[Product]],ProductName,2) -> Ultrathing V3 | M6: =VLOOKUP(K6,ProductName,4)*J6 -> 1056 | N6: =VLOOKUP(K6,ProductName,3)*M6 -> 3685.44 | O6: =YEAR(I6) -> 2009 | P6: =TEXT(I6,"MMM") -> Jun | R6: A3 | S6: Megawidget L | T6: 1.59 | U6: 24 | Z6: VLOOKUP(K3,ProductName,3)*M3
A7: 6 | B7: =Table6[[#This Row],[Initials]] -> V | C7: =Table6[[#This Row],[Last Name Correction]] -> Lundy | D7: Miss | E7: =Table6[[#This Row],[Gender Correction]] -> F | F7: 90 | G7: Katherine Gardens | H7: Ardgay | I7: 40316 | J7: 37 | K7: A3 | L7: =VLOOKUP(Portfolio43468[[#This Row],[Product]],ProductName,2) -> Megawidget L | M7: =VLOOKUP(K7,ProductName,4)*J7 -> 888 | N7: =VLOOKUP(K7,ProductName,3)*M7 -> 1411.92 | O7: =YEAR(I7) -> 2010 | P7: =TEXT(I7,"MMM") -> May | R7: B | S7: Hyperwotsit | T7: 2.01 | U7: 20
A8: 7 | B8: =Table6[[#This Row],[Initials]] -> V | C8: =Table6[[#This Row],[Last Name Correction]] -> Frost | D8: Mrs | E8: =Table6[[#This Row],[Gender Correction]] -> F | F8: 30 | G8: Ross Way | H8: Solihull | I8: 40202 | J8: 12 | K8: C2 | L8: =VLOOKUP(Portfolio43468[[#This Row],[Product]],ProductName,2) -> Ultrathing V2 | M8: =VLOOKUP(K8,ProductName,4)*J8 -> 240 | N8: =VLOOKUP(K8,ProductName,3)*M8 -> 717.6 | O8: =YEAR(I8) -> 2010 | P8: =TEXT(I8,"MMM") -> Jan | R8: C1 | S8: Ultrathing V1 | T8: 1.99 | U8: 17
A9: 8 | B9: =Table6[[#This Row],[Initials]] -> R | C9: =Table6[[#This Row],[Last Name Correction]] -> Woods | D9: Mrs | E9: =Table6[[#This Row],[Gender Correction]] -> F | F9: 30 | G9: Artisans Dwellings | H9: Tring | I9: 40497 | J9: 55 | K9: C1 | L9: =VLOOKUP(Portfolio43468[[#This Row],[Product]],ProductName,2) -> Ultrathing V1 | M9: =VLOOKUP(K9,ProductName,4)*J9 -> 935 | N9: =VLOOKUP(K9,ProductName,3)*M9 -> 1860.65 | O9: =YEAR(I9) -> 2010 | P9: =TEXT(I9,"MMM") -> Nov | R9: C2 | S9: Ultrathing V2 | T9: 2.99 | U9: 20
A10: 9 | B10: =Table6[[#This Row],[Initials]] -> K | C10: =Table6[[#This Row],[Last Name Correction]] -> Navarro | D10: Mrs | E10: =Table6[[#This Row],[Gender Correction]] -> F | F10: 30 | G10: Rhoda Street | H10: St. Ives | I10: 39938 | J10: 10 | K10: C3 | L10: =VLOOKUP(Portfolio43468[[#This Row],[Product]],ProductName,2) -> Ultrathing V3 | M10: =VLOOKUP(K10,ProductName,4)*J10 -> 240 | N10: =VLOOKUP(K10,ProductName,3)*M10 -> 837.6 | O10: =YEAR(I10) -> 2009 | P10: =TEXT(I10,"MMM") -> May | R10: C3 | S10: Ultrathing V3 | T10: 3.49 | U10: 24
A11: 10 | B11: =Table6[[#This Row],[Initials]] -> M | C11: =Table6[[#This Row],[Last Name Correction]] -> Anthony | D11: Miss | E11: =Table6[[#This Row],[Gender Correction]] -> F | F11: 90 | G11: Iceland Road | H11: Campbeltown | I11: 40466 | J11: 76 | K11: A2 | L11: =VLOOKUP(Portfolio43468[[#This Row],[Product]],ProductName,2) -> Megawidget M | M11: =VLOOKUP(K11,ProductName,4)*J11 -> 1824 | N11: =VLOOKUP(K11,ProductName,3)*M11 -> 2170.56 | O11: =YEAR(I11) -> 2010 | P11: =TEXT(I11,"MMM") -> Oct | R11: C4 | S11: Ultrathing V4 | T11: 3.99 | U11: 24
A12: 11 | B12: =Table6[[#This Row],[Initials]] -> S | C12: =Table6[[#This Row],[Last Name Correction]] -> Roland | D12: Mrs | E12: =Table6[[#This Row],[Gender Correction]] -> F | F12: 90 | G12: Samels Court | H12: Newbridge | I12: 40031 | J12: 28 | K12: C2 | L12: =VLOOKUP(Portfolio43468[[#This Row],[Product]],ProductName,2) -> Ultrathing V2 | M12: =VLOOKUP(K12,ProductName,4)*J12 -> 560 | N12: =VLOOKUP(K12,ProductName,3)*M12 -> 1674.4 | O12: =YEAR(I12) -> 2009 | P12: =TEXT(I12,"MMM") -> Aug | R12: D | S12: Gigastuff | T12: 1.89 | U12: 18
A13: 12 | B13: =Table6[[#This Row],[Initials]] -> Y | C13: =Table6[[#This Row],[Last Name Correction]] -> Culver | D13: Miss | E13: =Table6[[#This Row],[Gender Correction]] -> F | F13: 60 | G13: Garratt Green | H13: London | I13: 39965 | J13: 41 | K13: A2 | L13: =VLOOKUP(Portfolio43468[[#This Row],[Product]],ProductName,2) -> Megawidget M | M13: =VLOOKUP(K13,ProductName,4)*J13 -> 984 | N13: =VLOOKUP(K13,ProductName,3)*M13 -> 1170.96 | O13: =YEAR(I13) -> 2009 | P13: =TEXT(I13,"MMM") -> Jun | R13: E | S13: Superwossname | T13: 3.11 | U13: 20
A14: 13 | B14: =Table6[[#This Row],[Initials]] -> M | C14: =Table6[[#This Row],[Last Name Correction]] -> Doran | D14: Miss | E14: =Table6[[#This Row],[Gender Correction]] -> F | F14: 90 | G14: High St | H14: Caldicot | I14: 39516 | J14: 48 | K14: B | L14: =VLOOKUP(Portfolio43468[[#This Row],[Product]],ProductName,2) -> Hyperwotsit | M14: =VLOOKUP(K14,ProductName,4)*J14 -> 960 | N14: =VLOOKUP(K14,ProductName,3)*M14 -> 1929.6 | O14: =YEAR(I14) -> 2008 | P14: =TEXT(I14,"MMM") -> Mar
A15: 14 | B15: =Table6[[#This Row],[Initials]] -> L | C15: =Table6[[#This Row],[Last Name Correction]] -> Richards | D15: Prof | E15: =Table6[[#This Row],[Gender Correction]] -> F | F15: 90 | G15: Brackenfield Close | H15: Broseley | I15: 39665 | J15: 34 | K15: C4 | L15: =VLOOKUP(Portfolio43468[[#This Row],[Product]],ProductName,2) -> Ultrathing V4 | M15: =VLOOKUP(K15,ProductName,4)*J15 -> 816 | N15: =VLOOKUP(K15,ProductName,3)*M15 -> 3255.84 | O15: =YEAR(I15) -> 2008 | P15: =TEXT(I15,"MMM") -> Aug
A16: 15 | B16: =Table6[[#This Row],[Initials]] -> M | C16: =Table6[[#This Row],[Last Name Correction]] -> Wright | D16: Mrs | E16: =Table6[[#This Row],[Gender Correction]] -> F | F16: 60 | G16: Bearstead Rise | H16: Y Felinheli | I16: 40337 | J16: 57 | K16: C4 | L16: =VLOOKUP(Portfolio43468[[#This Row],[Product]],ProductName,2) -> Ultrathing V4 | M16: =VLOOKUP(K16,ProductName,4)*J16 -> 1368 | N16: =VLOOKUP(K16,ProductName,3)*M16 -> 5458.32 | O16: =YEAR(I16) -> 2010 | P16: =TEXT(I16,"MMM") -> Jun | R16: Method 1: Using SUMIFS Formula
A17: 16 | B17: =Table6[[#This Row],[Initials]] -> B | C17: =Table6[[#This Row],[Last Name Correction]] -> Vasquez | D17: Mrs | E17: =Table6[[#This Row],[Gender Correction]] -> F | F17: 30 | G17: Baker Road | H17: Trowbridge | I17: 40532 | J17: 59 | K17: E | L17: =VLOOKUP(Portfolio43468[[#This Row],[Product]],ProductName,2) -> Superwossname | M17: =VLOOKUP(K17,ProductName,4)*J17 -> 1180 | N17: =VLOOKUP(K17,ProductName,3)*M17 -> 3669.8 | O17: =YEAR(I17) -> 2010 | P17: =TEXT(I17,"MMM") -> Dec
A18: 17 | B18: =Table6[[#This Row],[Initials]] -> E | C18: =Table6[[#This Row],[Last Name Correction]] -> Butler | D18: Miss | E18: =Table6[[#This Row],[Gender Correction]] -> F | F18: 30 | G18: Telford Close | H18: Isles Of Scilly | I18: 40271 | J18: 84 | K18: C1 | L18: =VLOOKUP(Portfolio43468[[#This Row],[Product]],ProductName,2) -> Ultrathing V1 | M18: =VLOOKUP(K18,ProductName,4)*J18 -> 1428 | N18: =VLOOKUP(K18,ProductName,3)*M18 -> 2841.72 | O18: =YEAR(I18) -> 2010 | P18: =TEXT(I18,"MMM") -> Apr | R18: Year | S18: Jan | T18: Feb | U18: Mar | V18: Apr | W18: May | X18: Jun | Y18: Jul | Z18: Aug | AA18: Sep | AB18: Oct | AC18: Nov | AD18: Dec
A19: 18 | B19: =Table6[[#This Row],[Initials]] -> I | C19: =Table6[[#This Row],[Last Name Correction]] -> Hutchinson | D19: Ms | E19: =Table6[[#This Row],[Gender Correction]] -> F | F19: 30 | G19: Queens Buildings | H19: Kilmacolm | I19: 40183 | J19: 39 | K19: C4 | L19: =VLOOKUP(Portfolio43468[[#This Row],[Product]],ProductName,2) -> Ultrathing V4 | M19: =VLOOKUP(K19,ProductName,4)*J19 -> 936 | N19: =VLOOKUP(K19,ProductName,3)*M19 -> 3734.64 | O19: =YEAR(I19) -> 2010 | P19: =TEXT(I19,"MMM") -> Jan | R19: 2008 | S19: =SUMIFS($N$2:$N$1987,$O$2:$O$1987,$R19,$P$2:$P$1987,S$18) -> 153629.38 | T19: =SUMIFS($N$2:$N$1987,$O$2:$O$1987,$R19,$P$2:$P$1987,T$18) -> 83125.81 | U19: =SUMIFS($N$2:$N$1987,$O$2:$O$1987,$R19,$P$2:$P$1987,U$18) -> 131988.34 | V19: =SUMIFS($N$2:$N$1987,$O$2:$O$1987,$R19,$P$2:$P$1987,V$18) -> 115302.47 | W19: =SUMIFS($N$2:$N$1987,$O$2:$O$1987,$R19,$P$2:$P$1987,W$18) -> 142221.6 | X19: =SUMIFS($N$2:$N$1987,$O$2:$O$1987,$R19,$P$2:$P$1987,X$18) -> 150280.49 | Y19: =SUMIFS($N$2:$N$1987,$O$2:$O$1987,$R19,$P$2:$P$1987,Y$18) -> 161701.5 | Z19: =SUMIFS($N$2:$N$1987,$O$2:$O$1987,$R19,$P$2:$P$1987,Z$18) -> 162951.5 | ... AD19: =SUMIFS($N$2:$N$1987,$O$2:$O$1987,$R19,$P$2:$P$1987,AD$18) -> 151056.58
A20: 19 | B20: =Table6[[#This Row],[Initials]] -> W | C20: =Table6[[#This Row],[Last Name Correction]] -> Cabrera | D20: Miss | E20: =Table6[[#This Row],[Gender Correction]] -> F | F20: 90 | G20: Havelock Cottages | H20: Bridgwater | I20: 40381 | J20: 54 | K20: A1 | L20: =VLOOKUP(Portfolio43468[[#This Row],[Product]],ProductName,2) -> Megawidget S | M20: =VLOOKUP(K20,ProductName,4)*J20 -> 1296 | N20: =VLOOKUP(K20,ProductName,3)*M20 -> 1023.84 | O20: =YEAR(I20) -> 2010 | P20: =TEXT(I20,"MMM") -> Jul | R20: 2009 | S20: =SUMIFS($N$2:$N$1987,$O$2:$O$1987,$R20,$P$2:$P$1987,S$18) -> 125774.12 | T20: =SUMIFS($N$2:$N$1987,$O$2:$O$1987,$R20,$P$2:$P$1987,T$18) -> 88773.92 | U20: =SUMIFS($N$2:$N$1987,$O$2:$O$1987,$R20,$P$2:$P$1987,U$18) -> 122300.12 | V20: =SUMIFS($N$2:$N$1987,$O$2:$O$1987,$R20,$P$2:$P$1987,V$18) -> 135559.15 | W20: =SUMIFS($N$2:$N$1987,$O$2:$O$1987,$R20,$P$2:$P$1987,W$18) -> 147963.52 | X20: =SUMIFS($N$2:$N$1987,$O$2:$O$1987,$R20,$P$2:$P$1987,X$18) -> 138723.37 | Y20: =SUMIFS($N$2:$N$1987,$O$2:$O$1987,$R20,$P$2:$P$1987,Y$18) -> 129718.29 | Z20: =SUMIFS($N$2:$N$1987,$O$2:$O$1987,$R20,$P$2:$P$1987,Z$18) -> 123668.96 | ... AD20: =SUMIFS($N$2:$N$1987,$O$2:$O$1987,$R20,$P$2:$P$1987,AD$18) -> 126633.8
A21: 20 | B21: =Table6[[#This Row],[Initials]] -> C | C21: =Table6[[#This Row],[Last Name Correction]] -> Walsh | D21: Mrs | E21: =Table6[[#This Row],[Gender Correction]] -> F | F21: 90 | G21: Huntingdon Gardens | H21: Essex | I21: 40469 | J21: 33 | K21: C2 | L21: =VLOOKUP(Portfolio43468[[#This Row],[Product]],ProductName,2) -> Ultrathing V2 | M21: =VLOOKUP(K21,ProductName,4)*J21 -> 660 | N21: =VLOOKUP(K21,ProductName,3)*M21 -> 1973.4 | O21: =YEAR(I21) -> 2010 | P21: =TEXT(I21,"MMM") -> Oct | R21: 2010 | S21: =SUMIFS($N$2:$N$1987,$O$2:$O$1987,$R21,$P$2:$P$1987,S$18) -> 140157.75 | T21: =SUMIFS($N$2:$N$1987,$O$2:$O$1987,$R21,$P$2:$P$1987,T$18) -> 146532.92 | U21: =SUMIFS($N$2:$N$1987,$O$2:$O$1987,$R21,$P$2:$P$1987,U$18) -> 150135.42 | V21: =SUMIFS($N$2:$N$1987,$O$2:$O$1987,$R21,$P$2:$P$1987,V$18) -> 158124.82 | W21: =SUMIFS($N$2:$N$1987,$O$2:$O$1987,$R21,$P$2:$P$1987,W$18) -> 153677.69 | X21: =SUMIFS($N$2:$N$1987,$O$2:$O$1987,$R21,$P$2:$P$1987,X$18) -> 141835.32 | Y21: =SUMIFS($N$2:$N$1987,$O$2:$O$1987,$R21,$P$2:$P$1987,Y$18) -> 125377.45 | Z21: =SUMIFS($N$2:$N$1987,$O$2:$O$1987,$R21,$P$2:$P$1987,Z$18) -> 103154.58 | ... AD21: =SUMIFS($N$2:$N$1987,$O$2:$O$1987,$R21,$P$2:$P$1987,AD$18) -> 110212.95
A22: 21 | B22: =Table6[[#This Row],[Initials]] -> J | C22: =Table6[[#This Row],[Last Name Correction]] -> Farley | D22: Mrs | E22: =Table6[[#This Row],[Gender Correction]] -> F | F22: 60 | G22: Embankment Gardens | H22: Badminton | I22: 39587 | J22: 84 | K22: C2 | L22: =VLOOKUP(Portfolio43468[[#This Row],[Product]],ProductName,2) -> Ultrathing V2 | M22: =VLOOKUP(K22,ProductName,4)*J22 -> 1680 | N22: =VLOOKUP(K22,ProductName,3)*M22 -> 5023.2 | O22: =YEAR(I22) -> 2008 | P22: =TEXT(I22,"MMM") -> May
A23: 22 | B23: =Table6[[#This Row],[Initials]] -> G | C23: =Table6[[#This Row],[Last Name Correction]] -> Tipton | D23: Miss | E23: =Table6[[#This Row],[Gender Correction]] -> F | F23: 30 | G23: Burton Grove | H23: Halesowen | I23: 39993 | J23: 94 | K23: C1 | L23: =VLOOKUP(Portfolio43468[[#This Row],[Product]],ProductName,2) -> Ultrathing V1 | M23: =VLOOKUP(K23,ProductName,4)*J23 -> 1598 | N23: =VLOOKUP(K23,ProductName,3)*M23 -> 3180.02 | O23: =YEAR(I23) -> 2009 | P23: =TEXT(I23,"MMM") -> Jun | R23: Total Sales By Year | X23: To look at total sales by year and total sales by month we can use 2 methods
A24: 23 | B24: =Table6[[#This Row],[Initials]] -> C | C24: =Table6[[#This Row],[Last Name Correction]] -> Grace | D24: Miss | E24: =Table6[[#This Row],[Gender Correction]] -> F | F24: 90 | G24: Alliance Road | H24: Kyle | I24: 40470 | J24: 84 | K24: A1 | L24: =VLOOKUP(Portfolio43468[[#This Row],[Product]],ProductName,2) -> Megawidget S | M24: =VLOOKUP(K24,ProductName,4)*J24 -> 2016 | N24: =VLOOKUP(K24,ProductName,3)*M24 -> 1592.64 | O24: =YEAR(I24) -> 2010 | P24: =TEXT(I24,"MMM") -> Oct | R24: Year | S24: Total Sales | X24: 1. Using SUMIFS: Made a table listing all Years & Months
A25: 24 | B25: =Table6[[#This Row],[Initials]] -> K | C25: =Table6[[#This Row],[Last Name Correction]] -> Ragland | D25: Miss | E25: =Table6[[#This Row],[Gender Correction]] -> F | F25: 90 | G25: Coningsby Cottages | H25: Cradley Heath | I25: 40052 | J25: 37 | K25: A3 | L25: =VLOOKUP(Portfolio43468[[#This Row],[Product]],ProductName,2) -> Megawidget L | M25: =VLOOKUP(K25,ProductName,4)*J25 -> 888 | N25: =VLOOKUP(K25,ProductName,3)*M25 -> 1411.92 | O25: =YEAR(I25) -> 2009 | P25: =TEXT(I25,"MMM") -> Aug | R25: 2008 | S25: =SUM(S19:AD19) -> 1683780.7 | X25: Formula =SUMIFS($N$2:$N$1987,$O$2:$O$1987,$R19,$P$2:$P$1987,S$18)
A26: 25 | B26: =Table6[[#This Row],[Initials]] -> R | C26: =Table6[[#This Row],[Last Name Correction]] -> Crosby | D26: Miss | E26: =Table6[[#This Row],[Gender Correction]] -> F | F26: 60 | G26: Burdett Place | H26: Frizington | I26: 40006 | J26: 3 | K26: C2 | L26: =VLOOKUP(Portfolio43468[[#This Row],[Product]],ProductName,2) -> Ultrathing V2 | M26: =VLOOKUP(K26,ProductName,4)*J26 -> 60 | N26: =VLOOKUP(K26,ProductName,3)*M26 -> 179.4 | O26: =YEAR(I26) -> 2009 | P26: =TEXT(I26,"MMM") -> Jul | R26: 2009 | S26: =SUM(S20:AD20) -> 1520156.8 | X26: Used SUM function to calculate the Total Sales for 2008,2009,2010
A27: 26 | B27: =Table6[[#This Row],[Initials]] -> T | C27: =Table6[[#This Row],[Last Name Correction]] -> Stroud | D27: Mrs | E27: =Table6[[#This Row],[Gender Correction]] -> F | F27: 30 | G27: Biddenden Way | H27: Longfield | I27: 39893 | J27: 34 | K27: C1 | L27: =VLOOKUP(Portfolio43468[[#This Row],[Product]],ProductName,2) -> Ultrathing V1 | M27: =VLOOKUP(K27,ProductName,4)*J27 -> 578 | N27: =VLOOKUP(K27,ProductName,3)*M27 -> 1150.22 | O27: =YEAR(I27) -> 2009 | P27: =TEXT(I27,"MMM") -> Mar | R27: 2010 | S27: =SUM(S21:AD21) -> 1644229.8
A28: 27 | B28: =Table6[[#This Row],[Initials]] -> J | C28: =Table6[[#This Row],[Last Name Correction]] -> Austin | D28: Mrs | E28: =Table6[[#This Row],[Gender Correction]] -> F | F28: 30 | G28: Selhurst Road | H28: Downham Market | I28: 40308 | J28: 78 | K28: A3 | L28: =VLOOKUP(Portfolio43468[[#This Row],[Product]],ProductName,2) -> Megawidget L | M28: =VLOOKUP(K28,ProductName,4)*J28 -> 1872 | N28: =VLOOKUP(K28,ProductName,3)*M28 -> 2976.48 | O28: =YEAR(I28) -> 2010 | P28: =TEXT(I28,"MMM") -> May | R28: Total | S28: =SUM(Table10[Total Sales]) -> 4848167.3
A29: 28 | B29: =Table6[[#This Row],[Initials]] -> M | C29: =Table6[[#This Row],[Last Name Correction]] -> Marcus | D29: Mrs | E29: =Table6[[#This Row],[Gender Correction]] -> F | F29: 90 | G29: Lyons Yard | H29: Lyme Regis | I29: 39916 | J29: 46 | K29: A3 | L29: =VLOOKUP(Portfolio43468[[#This Row],[Product]],ProductName,2) -> Megawidget L | M29: =VLOOKUP(K29,ProductName,4)*J29 -> 1104 | N29: =VLOOKUP(K29,ProductName,3)*M29 -> 1755.36 | O29: =YEAR(I29) -> 2009 | P29: =TEXT(I29,"MMM") -> Apr
A30: 29 | B30: =Table6[[#This Row],[Initials]] -> A | C30: =Table6[[#This Row],[Last Name Correction]] -> Pryor | D30: Ms | E30: =Table6[[#This Row],[Gender Correction]] -> F | F30: 90 | G30: Edgar Road | H30: Cornwall | I30: 39906 | J30: 34 | K30: E | L30: =VLOOKUP(Portfolio43468[[#This Row],[Product]],ProductName,2) -> Superwossname | M30: =VLOOKUP(K30,ProductName,4)*J30 -> 680 | N30: =VLOOKUP(K30,ProductName,3)*M30 -> 2114.8 | O30: =YEAR(I30) -> 2009 | P30: =TEXT(I30,"MMM") -> Apr
A31: 30 | B31: =Table6[[#This Row],[Initials]] -> J | C31: =Table6[[#This Row],[Last Name Correction]] -> Simons | D31: Mrs | E31: =Table6[[#This Row],[Gender Correction]] -> F | F31: 30 | G31: Roe Lane | H31: Pentre | I31: 39670 | J31: 64 | K31: E | L31: =VLOOKUP(Portfolio43468[[#This Row],[Product]],ProductName,2) -> Superwossname | M31: =VLOOKUP(K31,ProductName,4)*J31 -> 1280 | N31: =VLOOKUP(K31,ProductName,3)*M31 -> 3980.8 | O31: =YEAR(I31) -> 2008 | P31: =TEXT(I31,"MMM") -> Aug | R31: Method 2: Using Pivot Table
A32: 31 | B32: =Table6[[#This Row],[Initials]] -> L | C32: =Table6[[#This Row],[Last Name Correction]] -> Emerson | D32: Miss | E32: =Table6[[#This Row],[Gender Correction]] -> F | F32: 90 | G32: Beaufort Wharf | H32: Cirencester | I32: 39552 | J32: 80 | K32: D | L32: =VLOOKUP(Portfolio43468[[#This Row],[Product]],ProductName,2) -> Gigastuff | M32: =VLOOKUP(K32,ProductName,4)*J32 -> 1440 | N32: =VLOOKUP(K32,ProductName,3)*M32 -> 2721.6 | O32: =YEAR(I32) -> 2008 | P32: =TEXT(I32,"MMM") -> Apr
A33: 32 | B33: =Table6[[#This Row],[Initials]] -> J | C33: =Table6[[#This Row],[Last Name Correction]] -> Oneal | D33: Miss | E33: =Table6[[#This Row],[Gender Correction]] -> F | F33: 60 | G33: Anns Close | H33: Ellesmere | I33: 40508 | J33: 88 | K33: B | L33: =VLOOKUP(Portfolio43468[[#This Row],[Product]],ProductName,2) -> Hyperwotsit | M33: =VLOOKUP(K33,ProductName,4)*J33 -> 1760 | N33: =VLOOKUP(K33,ProductName,3)*M33 -> 3537.6 | O33: =YEAR(I33) -> 2010 | P33: =TEXT(I33,"MMM") -> Nov | R33: Row Labels | S33: Sum of Order Value | U33: Row Labels | V33: Sum of Order Value | X33: 2. Using Pivot Tables: Inserted Pivot tables to show total sales by Year & Month
